Workbook

Sheet Locations
A1: # | B1: Brand | C1: Name | D1: Address | E1: City / Region | F1: Type | G1: Phone | H1: Email | I1: Website | J1: Needs Review | K1: Notes
A2: 1 | B2: NON | C2: PLEASE DONT TELL | D2: 113 Saint Marks Place, New York, New York 10009 | E2: New York, NY | F2: Cocktail Bar | H2: https://www.pdtnyc.com/private-events | I2: https://www.pdtnyc.com/
A3: 2 | B3: NON | C3: ROXY HOTEL | D3: 2 6th Avenue, New York, New York 10013 | E3: New York, NY | F3: Hotel | G3: (212) 519-6600 | H3: info@roxyhotelnyc.com. | I3: www.roxyhotelnyc.com
A4: 3 | B4: NON | C4: ATOMIX | D4: 104 East 30th Street, New York, New York 10016 | E4: New York, NY | F4: Korean Restaurant | H4: info@atomixnyc.com | I4: https://www.atomixnyc.com/
A5: 4 | B5: NON | C5: CROWN SHY | D5: 70 Pine Street, Manhattan, NY, 10005 | E5: Manhattan, NY | F5: American Restaurant | G5: +1-212-517-1932 | H5: info@crownshy.nyc. | I5: www.crownshy.nyc
A6: 5 | B6: NON | C6: HAPPIER GROCERY | D6: 369 Canal Street, New York, New York 10013 | E6: New York, NY | F6: Grocery Store | G6: (212) 837-8015 | H6: PARTNERSHIPS@HAPPIERGROCERY.COM | I6: https://www.happiergrocery.com/
A7: 6 | B7: NON | C7: ROSEMARYS | D7: 18 Greenwich Ave, New York, NY 10011 | E7: New York, NY | F7: Italian Restaurant | G7: +12126471818 | H7: info@rosemarysnyc.com | I7: https://www.rosemarysnyc.com/location/rosemarys-west-village/
A8: 7 | B8: NON | C8: SHOSH | D8: 41 Greenwich Avenue, New York, New York 10014 | E8: New York, NY | F8: Mediterranean Restaurant | G8: (646) 850-0297 | H8: info@shosh.nyc | I8: https://www.shosh.nyc/
A9: 8 | B9: NON | C9: THE MANNER | D9: 52 Thompson Street, New York, New York 10012 | E9: New York, NY | F9: Resort hotel | G9: (929) 526-3330 | H9: press@soho.themanner.com | I9: https://themanner.com/
A10: 9 | B10: NON | C10: JUA | D10: 36 East 22nd Street, New York, New York 10010 | E10: New York, NY | F10: Korean Restaurant | G10: 646-590-1598 | H10: info@juanyc.com | I10: www.juanyc.com
A11: 10 | B11: NON | C11: ETC VENUE | D11: East 54th Street, New York, New York 10022 | E11: New York, NY | F11: Event Venue | G11: (646) 844-6004
A12: 11 | B12: NON | C12: HAGS | D12: 167 1st Avenue, New York, New York 10003 | E12: New York, NY | F12: Fine Dining Restaurant | G12: (845) 871-2252 | H12: info@hagsnyc.com | I12: hagsnyc.com
A13: 12 | B13: NON | C13: TERROIR TRIBECA | D13: 24 Harrison Street, New York, New York 10013 | E13: New York, NY | F13: Wine Bar | G13: (212) 625-9463 | H13: info@wineisterroir.com | I13: https://www.wineisterroir.com/
A14: 13 | B14: NON | C14: CHEZ OSKAR | D14: 373 Decatur Street, New York, New York 11233 | E14: Brooklyn, NY | F14: French Restaurant | G14: +1-718-852-6250 | H14: Chezoskar310@gmail.com | I14: www.chezoskar.com
A15: 14 | B15: NON | C15: EAST VILLAGE FARM | D15: 69 2nd Ave, New York, NY 10003 | E15: New York, NY | F15: Grocery Store | G15: (212) 477-1385 | I15: https://www.mercato.com/shop/east-village-farm-grocery?srsltid=AfmBOoqFiZfLRoqCfy4PJYV5mMd-QnM9j0KQ2jbfCxt9nbqWAqIuFlzr
A16: 15 | B16: NON | C16: EDITION HOTELS | D16: 5 Madison Avenue, Manhattan, NY, 10010 | E16: Manhattan, NY | F16: Hotel | G16: (212) 413-4200 | H16: info.nyc@editionhotels.com | I16: https://www.editionhotels.com/
A17: 16 | B17: NON | C17: ROSEMARYS EAST | D17: 350 1st Avenue, New York, New York 10010 | E17: New York, NY | F17: Italian Restaurant | G17: (646) 868-5335 | H17: info@rosemarysnyc.com | I17: https://www.rosemarysnyc.com/location/rosemarys-east/
A18: 17 | B18: NON | C18: AMAN HOTEL | D18: 724 5th Avenue, New York, New York 10019 | E18: New York, NY | F18: Hotel | G18: +1 754 216 7830 | H18: reservations@aman.com
A19: 18 | B19: NON | C19: BAR MADONNA | D19: 367 Metropolitan Avenue, New York, New York 11211 | E19: Brooklyn, NY | F19: Restaurant | H19: reservations@barmadonna.com | I19: https://barmadonna.com/
A20: 19 | B20: NON | C20: PATISSERIE CHANSON | D20: 155 West 70th Street, New York, New York 10023 | E20: New York, NY | F20: Bakery | G20: CLOSED | H20: CLOSED
A21: 20 | B21: NON | C21: AVERY FISHER HALL/ Davud Geffen Hall | D21: 10 Lincoln Center Plaza, New York, NY 10023 | E21: New York, NY | F21: Performing Arts Theater | G21: (212) 875-5656 | H21: guestexperience@lincolncenter.org | I21: www.lincolncenter.org/venue/david-geffen-hall
A22: 21 | B22: NON | C22: MINUS MOONSHINE | D22: 433 Sterling Place, New York, New York 11238 | E22: Brooklyn, NY | F22: Non Alc Store | G22: (914) 485-7502 | H22: info@minusmoonshine.com | I22: minusmoonshine.com | K22: Great one! Small indepdent locally owned non alcholic spirts
A23: 22 | B23: NON | C23: PERGOLA | D23: 36 West 28th Street, New York, New York 10001 | E23: New York, NY | F23: Mediterranean Restaurant | G23: +1-212-679-4842 | H23: info@pergolanewyork.com | I23: www.pergolanewyork.com
A24: 23 | B24: NON | C24: Meadow Lane | D24: 361 Greenwich Street, New York, New York 10013 | E24: New York, NY | F24: Grocery Store | G24: NA | H24: info@meadowlane.nyc | I24: https://www.meadowlane.nyc/
A25: 24 | B25: NON | C25: GAGE & TOLLNER | D25: 372 Fulton Mall, Brooklyn, NY, 11201 | E25: Brooklyn, NY | F25: American Restaurant | G25: +1-347-689-3677 | H25: https://www.gageandtollner.com/contact-us/ | I25: www.gageandtollner.com
A26: 25 | B26: NON | C26: SAA | D26: 154 Scott Avenue, New York, New York 11237 | E26: Brooklyn, NY | F26: Club/Event Space | G26: @saabrooklyn | I26: https://www.saa.nyc/
A27: 26 | B27: NON | C27: CHEZ FIFI | D27: 140 East 74th Street, New York, New York 10021 | E27: New York, NY | F27: Restaurant | G27: NA | H27: reservations@chezfifinyc.com, events@chezfifinyc.com | I27: https://www.chezfifinyc.com/
A28: 27 | B28: NON | C28: SPIRITED AWAY | D28: 177 Mott Street, New York, New York 10012 | E28: New York, NY | F28: Liquor Store | G28: +1-929-277-2520 | H28: https://www.spiritedaway.co/pages/contact | I28: www.spiritedaway.co
C29: SMITH & MILLS Rockefeller Plz | D29: 30 Rockefeller Plz, New York, New York 10112 | E29: Manhattan, NY | F29: Cocktail Bar | G29: NA | H29: https://www.smithandmills.com/contact | I29: https://www.smithandmills.com/
A30: 28 | B30: NON | C30: SMITH & MILLS TriBeCa | D30: 71 North Moore Street, Manhattan, NY, 10013 | E30: Manhattan, NY | F30: Cocktail Bar | G30: NA | H30: https://www.smithandmills.com/contact | I30: https://www.smithandmills.com/
A31: 29 | B31: NON | C31: LAKE SIDE EMOTIONS | D31: 113 Main St, Stony Brook, NY 11790 | E31: Stony Brook, NY | F31: Liquor Store | G31: (631) 675-2750 | H31: info@lakesideemotions.com | I31: https://lakesideemotions.com/
A32: 30 | B32: NON | C32: HUSO | D32: 323A Greenwich Street, New York, NY 10013 | E32: New York, NY | F32: Fine Dining Restaurant | G32: 212-931-4876 | H32: huso@husony.com | I32: https://husony.com/contact-us/
A33: 31 | B33: NON | C33: BOBO RESTAURANT | D33: 181 West 10th Street, New York, New York 10014 | E33: New York, NY | F33: French Restaurant | G33: (212) 488-2626 | H33: https://www.bobonyc.com/contact/ | I33: https://www.bobonyc.com/
A34: 32 | B34: NON | C34: Quorum by Convene | D34: 1221 6th Ave, New York, NY 10020 | E34: New York, NY | F34: Event Venue | G34: (888) 730-7307 | H34: NA | I34: https://convene.com/locations/new-york-city/1221-avenue-of-the-americas/
A35: 33 | B35: NON | C35: AMOR Y AMARGO | D35: 97 Avenue A, New York, New York 10009 | E35: New York, NY | F35: Bar | G35: (833) 328-4588 | H35: speakup@overthrowhospitality.com | I35: https://www.amoryamargo.com/
A36: 34 | B36: NON | C36: GRAMERCY TAVERN | D36: 42 East 20th Street, New York, New York 10003 | E36: New York, NY | F36: American Restaurant | G36: +1 212-477-0777 | H36: gtavern@gramercytavern.com | I36: www.gramercytavern.com
A37: 35 | B37: NON | C37: KEY FOOD STORE #1830 | D37: 8772 18th Avenue, Brooklyn, NY 11214 | E37: Brooklyn, NY | F37: Supermarket | G37: (718) 331-5080 | H37: NA | I37: https://www.keyfood.com/stores/1160
A38: 36 | B38: NON | C38: FREVO | D38: 48 West 8th Street, New York, New York 10011 | E38: New York, NY | F38: Fine Dining Restaurant | G38: (646) 455-0804 | H38: NA | I38: https://frevonyc.com/
A39: 37 | B39: NON | C39: LE CHENE | D39: 76 Carmine Street, New York, New York 10014 | E39: New York, NY | F39: French Restaurant | H39: bonjour@lechenenyc.com | I39: https://www.lechenenyc.com/
A40: 38 | B40: NON | C40: SU'JUK | D40: 216 Greene Avenue, New York, New York 11238 | E40: Brooklyn, NY | F40: Clothing Store | G40: +1-914-573-7545 | H40: https://www.sujukbk.com/pages/contact | I40: www.sujukbk.com
...

Sheet Legend & Summary
A1: Astra — Competitor + Prospect List
A2: Source: Astra Competitor + Stock List Navigator export (New York filter, 203 of 2,795 locations). Provided by user.
A4: How to use
A5: Yellow cells | B5: Blank in the source — these are the ones to fill in.
A6: Pink 'Needs Review' | B6: Flagged for review in the source system. Others are unflagged.
A7: Notes (col K) | B7: Free text — yours to use however you like.
A8: Filters | B8: Row 1 has filters on; the Brand column sorts back to source order via column A.
A9: Phone / Email | B9: Formatted as text so Excel won't reformat numbers or strip the leading +.
A10: Careful with | B10: Don't delete rows — the counts below reference the full range A2:K204.
A12: Example of the format expected in a filled row
A13: Brand | B13: Name | C13: Address | D13: City / Region | E13: Type | F13: Phone | G13: Email | H13: Website
A14: Prospects | B14: Rhodora | C14: 197 Adelphi St, Brooklyn, NY 11205 | D14: Brooklyn, NY | E14: wine bar | F14: +1 718-834-8410 | G14: hello@rhodorawinebar.com | H14: www.rhodorawinebar.com
A15: (Illustrative only — the phone, email and website above are made up, not researched. Do not copy them into the Locations tab.)
A17: Counts by brand
A18: Brand | B18: Locations | C18: Missing phone | D18: Missing email | E18: Missing website | F18: Missing type
A19: NON | B19: =COUNTIF(Locations!$B$2:$B$207,$A19) -> 79 | C19: =COUNTIFS(Locations!$B$2:$B$207,$A19,Locations!$G$2:$G$207,"") -> 4 | D19: =COUNTIFS(Locations!$B$2:$B$207,$A19,Locations!$H$2:$H$207,"") -> 3 | E19: =COUNTIFS(Locations!$B$2:$B$207,$A19,Locations!$I$2:$I$207,"") -> 5 | F19: =COUNTIFS(Locations!$B$2:$B$207,$A19,Locations!$F$2:$F$207,"") -> 0
A20: Prospects | B20: =COUNTIF(Locations!$B$2:$B$207,$A20) -> 43 | C20: =COUNTIFS(Locations!$B$2:$B$207,$A20,Locations!$G$2:$G$207,"") -> 0 | D20: =COUNTIFS(Locations!$B$2:$B$207,$A20,Locations!$H$2:$H$207,"") -> 0 | E20: =COUNTIFS(Locations!$B$2:$B$207,$A20,Locations!$I$2:$I$207,"") -> 0 | F20: =COUNTIFS(Locations!$B$2:$B$207,$A20,Locations!$F$2:$F$207,"") -> 0
A21: Savoure | B21: =COUNTIF(Locations!$B$2:$B$207,$A21) -> 11 | C21: =COUNTIFS(Locations!$B$2:$B$207,$A21,Locations!$G$2:$G$207,"") -> 0 | D21: =COUNTIFS(Locations!$B$2:$B$207,$A21,Locations!$H$2:$H$207,"") -> 2 | E21: =COUNTIFS(Locations!$B$2:$B$207,$A21,Locations!$I$2:$I$207,"") -> 0 | F21: =COUNTIFS(Locations!$B$2:$B$207,$A21,Locations!$F$2:$F$207,"") -> 0
A22: Unified Ferments | B22: =COUNTIF(Locations!$B$2:$B$207,$A22) -> 72 | C22: =COUNTIFS(Locations!$B$2:$B$207,$A22,Locations!$G$2:$G$207,"") -> 49 | D22: =COUNTIFS(Locations!$B$2:$B$207,$A22,Locations!$H$2:$H$207,"") -> 71 | E22: =COUNTIFS(Locations!$B$2:$B$207,$A22,Locations!$I$2:$I$207,"") -> 37 | F22: =COUNTIFS(Locations!$B$2:$B$207,$A22,Locations!$F$2:$F$207,"") -> 72
A23: Total | B23: =SUM(B19:B22) -> 205 | C23: =SUM(C19:C22) -> 53 | D23: =SUM(D19:D22) -> 76 | E23: =SUM(E19:E22) -> 42 | F23: =SUM(F19:F22) -> 72
A25: Flagged 'Needs Review' | B25: =COUNTIF(Locations!$J$2:$J$207,"Yes") -> 6
